Workbook
Name CountryStateMap: DropdownData!D2:E10407
Name StateCityMap: DropdownData!F2:G32598

Sheet Contact Template
A1: First Name | B1: Last Name | C1: Email | D1: LinkedIn | E1: Country | F1: State | G1: City | H1: Country Code | I1: Phone | J1: Tags | K1: Note
A2: Surya | B2: Chandra | C2: Surya.chandra@hot mail.com | E2: India | F2: Telangana | G2: Hyderabad | H2: =IF(E2="", "", VLOOKUP(E2,DropdownData!$H$2:$I$243,2,FALSE)) -> +91 | I2: 9973898644
A3: Mongoli | B3: needu | C3: mangoli.needu@hotmail.com | E3: India | F3: Telangana | G3: Hyderabad | H3: =IF(E3="", "", VLOOKUP(E3,DropdownData!$H$2:$I$243,2,FALSE)) -> +91 | I3: 6758888934
A4: Henfew | B4: stinil | C4: henfew.stinil@hotmail.com | E4: India | F4: Telangana | G4: Hyderabad | H4: =IF(E4="", "", VLOOKUP(E4,DropdownData!$H$2:$I$243,2,FALSE)) -> +91 | I4: 7785898867
H5: =IF(E5="", "", VLOOKUP(E5,DropdownData!$H$2:$I$243,2,FALSE))
H6: =IF(E6="", "", VLOOKUP(E6,DropdownData!$H$2:$I$243,2,FALSE))
H7: =IF(E7="", "", VLOOKUP(E7,DropdownData!$H$2:$I$243,2,FALSE))
H8: =IF(E8="", "", VLOOKUP(E8,DropdownData!$H$2:$I$243,2,FALSE))
H9: =IF(E9="", "", VLOOKUP(E9,DropdownData!$H$2:$I$243,2,FALSE))
H10: =IF(E10="", "", VLOOKUP(E10,DropdownData!$H$2:$I$243,2,FALSE))
H11: =IF(E11="", "", VLOOKUP(E11,DropdownData!$H$2:$I$243,2,FALSE))
H12: =IF(E12="", "", VLOOKUP(E12,DropdownData!$H$2:$I$243,2,FALSE))
H13: =IF(E13="", "", VLOOKUP(E13,DropdownData!$H$2:$I$243,2,FALSE))
H14: =IF(E14="", "", VLOOKUP(E14,DropdownData!$H$2:$I$243,2,FALSE))
H15: =IF(E15="", "", VLOOKUP(E15,DropdownData!$H$2:$I$243,2,FALSE))
H16: =IF(E16="", "", VLOOKUP(E16,DropdownData!$H$2:$I$243,2,FALSE))
... H1000: =IF(E1000="", "", VLOOKUP(E1000,DropdownData!$H$2:$I$243,2,FALSE))

Sheet Location Data
A1: Countries | B1: States | C1: Cities
A2: Algeria | B2: Constantine Province | C2: Constantine
A3: Andorra | B3: nan | C3: Escaldes-Engordany
A4: Angola | B4: nan | C4: Cacuaco
A5: Angola | B5: Cabinda Province | C5: Cabinda
A6: Armenia | B6: nan | C6: Ejmiatsin
A7: Armenia | B7: nan | C7: Charentsavan
A8: Azerbaijan | B8: nan | C8: Satrovka
A9: Bahrain | B9: Muharraq Governorate | C9: Al Muharraq
A10: Bahrain | B10: nan | C10: Al Malikiyah
A11: Bangladesh | B11: nan | C11: Rangapukur
A12: Bangladesh | B12: Rajshahi District | C12: Sirajganj
... A2039: United States | B2039: Washington | C2039: Seattle
A2042: Dropdown Lists
A2043: Afghanistan
A2044: Albania
A2045: Algeria
A2046: American Samoa
A2047: Andorra
A2048: Angola
A2049: Anguilla
A2050: Antigua and Barbuda
A2051: Argentina
A2052: Armenia
A2053: Aruba
... A2284: Zimbabwe
B2285: States
B2286: 'Adan Governorate
B2287: A'ana
B2288: Abia State
B2289: Acquaviva
B2290: Ad Dakhiliyah Governorate
B2291: Adamawa
B2292: Adana Province
B2293: Addis Ababa
B2294: Addu Atoll
B2295: Adjara
B2296: Agadez Region
... B3166: Ã˜stfold
C3167: Cities
...

Sheet DropdownData
A1: Countries | B1: States | C1: Cities | D1: Country | E1: State | F1: State | G1: City | H1: Country | I1: CountryCode
A2: Afghanistan | B2: 'Adan Governorate | C2: 'Abasan al Kabirah | D2: Algeria | E2: Algiers Province | F2: Constantine Province | G2: Constantine | H2: Afghanistan
A3: Albania | B3: A'ana | C3: 'Ajlun | D3: Algeria | E3: Annaba Province | F3: Cabinda Province | G3: Cabinda | H3: Albania
A4: Algeria | B4: Abia State | C4: 'Ajman | D4: Algeria | E4: Batna Province | F4: Muharraq Governorate | G4: Al Muharraq | H4: Algeria
A5: American Samoa | B5: Acquaviva | C5: Aalborg | D5: Algeria | E5: Biskra | F5: Rajshahi District | G5: Rajshahi | H5: American Samoa
A6: Andorra | B6: Ad Dakhiliyah Governorate | C6: Aarhus | D6: Algeria | E6: Constantine Province | F6: Rajshahi District | G6: Sirajganj | H6: Andorra
A7: Angola | B7: Adamawa | C7: Aasiaat | D7: Algeria | E7: M'Sila Province | F7: Stann Creek District | G7: Dangriga | H7: Angola
A8: Anguilla | B8: Adana Province | C8: Aba | D8: Algeria | E8: Oran Province | F8: Samdrup Jongkhar District | G8: Samdrup Jongkhar | H8: Anguilla
A9: Antigua and Barbuda | B9: Addis Ababa | C9: Abeche | D9: Andorra | E9: Andorra la Vella | F9: Kweneng District | G9: Mogoditshane | H9: Antigua and Barbuda
A10: Argentina | B10: Addu Atoll | C10: Aberdeen | D10: Andorra | E10: Canillo | F10: Kweneng District | G10: Molepolole | H10: Argentina
A11: Armenia | B11: Adjara | C11: Abidjan | D11: Andorra | E11: Encamp | F11: Bahia | G11: Salvador | H11: Armenia
A12: Aruba | B12: Agadez Region | C12: Abomey-Calavi | D12: Andorra | E12: La Massana | F12: Brunei-Muara District | G12: Bandar Seri Begawan | H12: Aruba
A13: Australia | B13: Aichi Prefecture | C13: Abovyan | D13: Andorra | E13: Ordino | F13: Temburong District | G13: Bangar | H13: Australia | I13: +61
A14: Austria | B14: Ainaro Municipality | C14: Abu Dhabi | D14: Andorra | E14: Sant Julia de Loria | F14: Cibitoke Province | G14: Cibitoke | H14: Austria
A15: Azerbaijan | B15: Al Ahmadi Governorate | C15: Abu Hulayfah | D15: Angola | E15: Benguela Province | F15: Littoral | G15: Douala | H15: Azerbaijan
A16: Bahamas, The | B16: Al Batinah North Governorate | C16: Abuja | D16: Angola | E16: Cabinda Province | F16: Littoral | G16: Nkongsamba | H16: Bahamas, The
A17: Bahrain | B17: Al Hudaydah Governorate | C17: Accra | D17: Angola | E17: Huambo Province | F17: Ouham Prefecture | G17: Bossangoa | H17: Bahrain
A18: Bangladesh | B18: Al Khor | C18: Acharnes | D18: Angola | E18: Luanda Province | F18: Bahr el Gazel | G18: Moussoro | H18: Bangladesh | I18: +880
A19: Barbados | B19: Al Madinah Region | C19: Aconibe | D19: Angola | E19: Malanje Province | F19: Alajuela Province | G19: San Jose | H19: Barbados
A20: Belarus | B20: Al Rayyan Municipality | C20: Acquaviva | D20: Armenia | E20: Ararat Province | F20: Alajuela Province | G20: San Rafael | H20: Belarus
A21: Belgium | B21: Al Wakrah | C21: Ad Dammam | D21: Armenia | E21: Armavir Region | F21: Alajuela Province | G21: San Ramon | H21: Belgium
A22: Belize | B22: Al-Hasakah Governorate | C22: Ad Diraz | D22: Armenia | E22: Kotayk Region | F22: Guanacaste Province | G22: Liberia | H22: Belize
A23: Benin | B23: Al-Raqqah Governorate | C23: Adamstown | D23: Armenia | E23: Lori Region | F23: Guanacaste Province | G23: Nicoya | H23: Benin
A24: Bermuda | B24: Al-Shahaniya | C24: Adana | D24: Armenia | E24: Shirak Region | F24: Guanacaste Province | G24: Santa Cruz | H24: Bermuda
A25: Bhutan | B25: Alabama | C25: Adda-Doueni | D25: Armenia | E25: Syunik Province | F25: Zagreb | G25: Sesvete | H25: Bhutan
A26: Bolivia | B26: Alagoas | C26: Addis Ababa | D26: Armenia | E26: Yerevan | F26: Zagreb | G26: Zagreb | H26: Bolivia
A27: Bonaire, Sint Eustatius, and Saba | B27: Alajuela Province | C27: Adelaide | D27: Azerbaijan | E27: Baku | F27: Havana Province | G27: Arroyo Naranjo | H27: Bonaire, Sint Eustatius, and Saba
A28: Bosnia and Herzegovina | B28: Alaska | C28: Aden | D28: Bahrain | E28: Capital Governorate | F28: Havana Province | G28: Havana | H28: Bosnia and Herzegovina
A29: Botswana | B29: Albay | C29: Adi Keyh | D29: Bahrain | E29: Central Governorate | F29: Region of Southern Denmark | G29: Esbjerg | H29: Botswana
A30: Brazil | B30: Alberta | C30: Adilabad | D30: Bahrain | E30: Muharraq Governorate | F30: Region of Southern Denmark | G30: Kolding | H30: Brazil | I30: +55
A31: Brunei | B31: Alborz Province | C31: Afega | D31: Bangladesh | E31: Dhaka District | F31: Region of Southern Denmark | G31: Odense | H31: Brunei
A32: Bulgaria | B32: Aleppo Governorate | C32: Agadez | D32: Bangladesh | E32: Khulna District | F32: Region of Southern Denmark | G32: Vejle | H32: Bulgaria
A33: Burkina Faso | B33: Alexandria Governorate | C33: Agadir | D33: Bangladesh | E33: Mymensingh District | F33: Puerto Plata Province | G33: Puerto Plata | H33: Burkina Faso
A34: Burma | B34: Algiers Province | C34: Aguadilla | D34: Bangladesh | E34: Rajshahi District | F34: Giza Governorate | G34: Giza | H34: Burma
A35: Burundi | B35: Alibori Department | C35: Aguadulce | D35: Bangladesh | E35: Sylhet District | F35: Litoral Province | G35: Bata | H35: Burundi
A36: Cabo Verde | B36: Almaty | C36: Ahmedabad | D36: Belgium | E36: Brussels-Capital Region | F36: Litoral Province | G36: Mbini | H36: Cabo Verde
A37: Cambodia | B37: Alta Verapaz Department | C37: Ahuachapan | D37: Belgium | E37: Flanders | F37: Occitania | G37: Montpellier | H37: Cambodia
A38: Cameroon | B38: Alytus City Municipality | C38: Ahvaz | D38: Belgium | E38: Liege | F38: Occitania | G38: Toulouse | H38: Cameroon
A39: Canada | B39: Amambay Department | C39: Ainaro | D39: Belgium | E39: Wallonia | F39: Mamou Region | G39: Mamou | H39: Canada
A40: Cayman Islands | B40: Amman Governorate | C40: Ajdabiya | D40: Belize | E40: Belize District | F40: Oio Region | G40: Bissora | H40: Cayman Islands
...

Sheet Instructions
A1: Contact Template Instructions
A3: PHONE NUMBER FORMAT:
A4: Option 1: Use separate columns (Recommended)
A5: - Column H (Country Code): Enter country code (e.g., +1, +91)
A6: - Column I (Phone): Enter phone number (e.g., 9876543210)
A8: Option 2: Use Phone column only
A9: - Column I (Phone): Enter as 'country_code:number' (e.g., +1:9876543210)
A10: - Multiple phones: Separate with '|' (e.g., +1:9876543210|+91:8765432109)
A12: LOCATION DROPDOWNS:
A13: 1. Select a country in column E
A14: 2. The state dropdown in column F will show only states for that country
A15: 3. Select a state in column F
... A24: - Phone is optional but recommended
